[2025-02-02T13:02:28.982+0000] {local_task_job_runner.py:123} INFO - ::group::Pre task execution logs
[2025-02-02T13:02:28.997+0000] {taskinstance.py:2613} INFO - Dependencies all met for dep_context=non-requeueable deps ti=<TaskInstance: forecasting_by_hour_v5.run_forecasting manual__2025-02-02T13:02:27.803057+00:00 [queued]>
[2025-02-02T13:02:29.003+0000] {taskinstance.py:2613} INFO - Dependencies all met for dep_context=requeueable deps ti=<TaskInstance: forecasting_by_hour_v5.run_forecasting manual__2025-02-02T13:02:27.803057+00:00 [queued]>
[2025-02-02T13:02:29.004+0000] {taskinstance.py:2866} INFO - Starting attempt 1 of 2
[2025-02-02T13:02:29.014+0000] {taskinstance.py:2889} INFO - Executing <Task(PythonOperator): run_forecasting> on 2025-02-02 13:02:27.803057+00:00
[2025-02-02T13:02:29.021+0000] {standard_task_runner.py:104} INFO - Running: ['***', 'tasks', 'run', 'forecasting_by_hour_v5', 'run_forecasting', 'manual__2025-02-02T13:02:27.803057+00:00', '--job-id', '129', '--raw', '--subdir', 'DAGS_FOLDER/forecasting_by_hour.py', '--cfg-path', '/tmp/tmpxun67_y8']
[2025-02-02T13:02:29.023+0000] {standard_task_runner.py:105} INFO - Job 129: Subtask run_forecasting
[2025-02-02T13:02:29.023+0000] {logging_mixin.py:190} WARNING - /home/***/.local/lib/python3.12/site-packages/***/task/task_runner/standard_task_runner.py:70 DeprecationWarning: This process (pid=84415) is multi-threaded, use of fork() may lead to deadlocks in the child.
[2025-02-02T13:02:29.024+0000] {standard_task_runner.py:72} INFO - Started process 84416 to run task
[2025-02-02T13:02:29.060+0000] {task_command.py:467} INFO - Running <TaskInstance: forecasting_by_hour_v5.run_forecasting manual__2025-02-02T13:02:27.803057+00:00 [running]> on host 6f5fd3382d74
[2025-02-02T13:02:29.137+0000] {taskinstance.py:3132} INFO - Exporting env vars: AIRFLOW_CTX_DAG_OWNER='***' AIRFLOW_CTX_DAG_ID='forecasting_by_hour_v5' AIRFLOW_CTX_TASK_ID='run_forecasting' AIRFLOW_CTX_EXECUTION_DATE='2025-02-02T13:02:27.803057+00:00' AIRFLOW_CTX_TRY_NUMBER='1' AIRFLOW_CTX_DAG_RUN_ID='manual__2025-02-02T13:02:27.803057+00:00'
[2025-02-02T13:02:29.138+0000] {taskinstance.py:731} INFO - ::endgroup::
[2025-02-02T13:02:29.237+0000] {logging_mixin.py:190} INFO - Erreur lors de l'exécution du script de prévision : Command '['ssh', 'hans@192.168.49.1', 'python3 ~/projet_eng_data_354/ml/forecasting.py']' returned non-zero exit status 255.
[2025-02-02T13:02:29.238+0000] {python.py:240} INFO - Done. Returned value was: None
[2025-02-02T13:02:29.246+0000] {taskinstance.py:340} INFO - ::group::Post task execution logs
[2025-02-02T13:02:29.246+0000] {taskinstance.py:352} INFO - Marking task as SUCCESS. dag_id=forecasting_by_hour_v5, task_id=run_forecasting, run_id=manual__2025-02-02T13:02:27.803057+00:00, execution_date=20250202T130227, start_date=20250202T130228, end_date=20250202T130229
[2025-02-02T13:02:29.279+0000] {local_task_job_runner.py:266} INFO - Task exited with return code 0
[2025-02-02T13:02:29.292+0000] {taskinstance.py:3895} INFO - 0 downstream tasks scheduled from follow-on schedule check
[2025-02-02T13:02:29.294+0000] {local_task_job_runner.py:245} INFO - ::endgroup::
